Workbook
Name l_scenario: 'Scenario sheet'!$B$7:$B$9
Name S_scenario: 'Scenario sheet'!$D$7

Sheet Model
B2: Geregu PLC
B3: Financial Forecast 2026- 2030
E4: 2024 | F4: 2025 | G4: =F4+1 -> 2026 | H4: =G4+1 -> 2027 | I4: =H4+1 -> 2028 | J4: =I4+1 -> 2029 | K4: =J4+1 -> 2030
B6: INCOME STATEMENT
B8: Revenue | E8: 137126532 | F8: 184935803 | G8: ='Assumption sheet'!F55 -> 2.2397997e+08 | H8: ='Assumption sheet'!G55 -> 2.5009535e+08 | I8: ='Assumption sheet'!H55 -> 2.7104135e+08 | J8: ='Assumption sheet'!I55 -> 2.9257093e+08 | K8: ='Assumption sheet'!J55 -> 3.146841e+08
B9: Cost of Sales | E9: -69865917 | F9: -100416543 | G9: =-'Assumption sheet'!F60 -> -1.2704092e+08 | H9: =-'Assumption sheet'!G60 -> -1.4284028e+08 | I9: =-'Assumption sheet'!H60 -> -1.5576134e+08 | J9: =-'Assumption sheet'!I60 -> -1.6908872e+08 | K9: =-'Assumption sheet'!J60 -> -1.828235e+08
B10: Gross Profit | E10: =SUM(E8:E9) -> 67260615 | F10: =SUM(F8:F9) -> 84519260 | G10: =SUM(G8:G9) -> 96939048 | H10: =SUM(H8:H9) -> 1.0725507e+08 | I10: =SUM(I8:I9) -> 1.1528001e+08 | J10: =SUM(J8:J9) -> 1.2348221e+08 | K10: =SUM(K8:K9) -> 1.318606e+08
B11: Other Income / (Loss) | E11: -583766 | F11: 1804896 | G11: 0 | H11: 0 | I11: 0 | J11: 0 | K11: 0
B12: SG&A Expenses | E12: -9354039 | F12: -17414424 | G12: =F12*(1+'Scenario sheet'!E12) -> -20549020 | H12: =G12*(1+'Scenario sheet'!F12) -> -23631373 | I12: =H12*(1+'Scenario sheet'!G12) -> -26467138 | J12: =I12*(1+'Scenario sheet'!H12) -> -29113852 | K12: =J12*(1+'Scenario sheet'!I12) -> -31879668
B13: Impairment Charge on Financial Assets | E13: -9401952 | F13: -10046707 | G13: =F13 -> -10046707 | H13: =G13 -> -10046707 | I13: =H13 -> -10046707 | J13: =I13 -> -10046707 | K13: =J13 -> -10046707
B14: EBITDA | E14: =SUM(E10:E13) -> 47920858 | F14: =SUM(F10:F13) -> 58863025 | G14: =SUM(G10:G13) -> 66343321 | H14: =SUM(H10:H13) -> 73576989 | I14: =SUM(I10:I13) -> 78766160 | J14: =SUM(J10:J13) -> 84321649 | K14: =SUM(K10:K13) -> 89934226
B15: Total Depreciation & Amortization (D&A) | E15: -4968135 | F15: -10713581 | G15: ='Assumption sheet'!F66 -> -9731551.6 | H15: ='Assumption sheet'!G66 -> -8827196.1 | I15: ='Assumption sheet'!H66 -> -8107690.8 | J15: ='Assumption sheet'!I66 -> -7583393.3 | K15: ='Assumption sheet'!J66 -> -7344766.8
B16: Operating Profit (EBIT) | E16: =SUM(E14:E15) -> 42952723 | F16: =SUM(F14:F15) -> 48149444 | G16: =SUM(G14:G15) -> 56611769 | H16: =SUM(H14:H15) -> 64749793 | I16: =SUM(I14:I15) -> 70658470 | J16: =SUM(J14:J15) -> 76738256 | K16: =SUM(K14:K15) -> 82589459
B17: Finance Income | E17: 8540399 | F17: 6425133 | G17: =15%*(AVERAGE(F36:G36)) -> 2426003.6 | H17: =15%*(AVERAGE(G36:H36)) -> 75000 | I17: =15%*(AVERAGE(H36:I36)) -> 239671.03 | J17: =15%*(AVERAGE(I36:J36)) -> 239671.03 | K17: =15%*(AVERAGE(J36:K36)) -> 166175.19
B18: Finance Cost | E18: -10227034 | F18: -12589544 | G18: =-'Assumption sheet'!F126 -> -14956552 | H18: =-'Assumption sheet'!G126 -> -16192793 | I18: =-'Assumption sheet'!H126 -> -15897467 | J18: =-'Assumption sheet'!I126 -> -13932953 | K18: =-'Assumption sheet'!J126 -> -11354315
B19: Profit Before Income Tax (PBT) | E19: =SUM(E16:E18) -> 41266088 | F19: =SUM(F16:F18) -> 41985033 | G19: =SUM(G16:G18) -> 44081221 | H19: =SUM(H16:H18) -> 48632000 | I19: =SUM(I16:I18) -> 55000673 | J19: =SUM(J16:J18) -> 63044973 | K19: =SUM(K16:K18) -> 71401320
B20: Income Tax Expense | E20: -13841019 | F20: -14734530 | G20: =-'Assumption sheet'!F91 -> -14387836 | H20: =-'Assumption sheet'!G91 -> -16230334 | I20: =-'Assumption sheet'!H91 -> -18472341 | J20: =-'Assumption sheet'!I91 -> -21275199 | K20: =-'Assumption sheet'!J91 -> -24259957
B21: Profit for the Year (Net Income) | E21: =SUM(E19:E20) -> 27425069 | F21: =SUM(F19:F20) -> 27250503 | G21: =SUM(G19:G20) -> 29693385 | H21: =SUM(H19:H20) -> 32401666 | I21: =SUM(I19:I20) -> 36528332 | J21: =SUM(J19:J20) -> 41769775 | K21: =SUM(K19:K20) -> 47141363
B23: BALANCE SHEET
B25: ASSETS
B26: Non-Current Assets
B27: Property, Plant and Equipment | E27: 72657733 | F27: 63050211 | G27: ='Assumption sheet'!F67 -> 56972259 | H27: ='Assumption sheet'!G67 -> 51896493 | I27: ='Assumption sheet'!H67 -> 48098360 | J27: ='Assumption sheet'!I67 -> 45430158 | K27: ='Assumption sheet'!J67 -> 45155300
B28: Intangible Assets | E28: 29 | F28: 0 | G28: 0 | H28: 0 | I28: 0 | J28: 0 | K28: 0
B29: Defined Benefit Plan Asset | E29: 11967 | F29: 50272 | G29: =F29 -> 50272 | H29: =G29 -> 50272 | I29: =H29 -> 50272 | J29: =I29 -> 50272 | K29: =J29 -> 50272
B30: Total Non-Current Assets | E30: =SUM(E27:E29) -> 72669729 | F30: =SUM(F27:F29) -> 63100483 | G30: =SUM(G27:G29) -> 57022531 | H30: =SUM(H27:H29) -> 51946765 | I30: =SUM(I27:I29) -> 48148632 | J30: =SUM(J27:J29) -> 45480430 | K30: =SUM(K27:K29) -> 45205572
B32: Current Assets
B33: Inventories | E33: 623675 | F33: 1314923 | G33: ='Assumption sheet'!F72 -> 1398811.1 | H33: ='Assumption sheet'!G72 -> 1721610.9 | I33: ='Assumption sheet'!H72 -> 1796194 | J33: ='Assumption sheet'!I72 -> 1993928.5 | K33: ='Assumption sheet'!J72 -> 2132079.3
B34: Trade and Other Receivables | E34: 121820410 | F34: 201108440 | G34: ='Assumption sheet'!F77 -> 2.2127312e+08 | H34: ='Assumption sheet'!G77 -> 2.5951954e+08 | I34: ='Assumption sheet'!H77 -> 2.745103e+08 | J34: ='Assumption sheet'!I77 -> 2.9995557e+08 | K34: ='Assumption sheet'!J77 -> 3.2066924e+08
B35: Other Current Assets | E35: 8420962 | F35: 7634826 | G35: =F35 -> 7634826 | H35: =G35 -> 7634826 | I35: =H35 -> 7634826 | J35: =I35 -> 7634826 | K35: =J35 -> 7634826
B36: Cash and Cash Equivalents | E36: 39935627 | F36: 31846715 | G36: =G90 -> 500000 | H36: =H90 -> 500000 | I36: =I90 -> 2695613.7 | J36: =J90 -> 500000 | K36: =K90 -> 1715669.2
B37: Total Current Assets | E37: =SUM(E33:E36) -> 170800674 | F37: =SUM(F33:F36) -> 241904904 | G37: =SUM(G33:G36) -> 2.3080676e+08 | H37: =SUM(H33:H36) -> 2.6937598e+08 | I37: =SUM(I33:I36) -> 2.8663693e+08 | J37: =SUM(J33:J36) -> 3.1008432e+08 | K37: =SUM(K33:K36) -> 3.3215182e+08
B38: TOTAL ASSETS | E38: =E37+E30 -> 243470403 | F38: =F37+F30 -> 305005387 | G38: =G37+G30 -> 2.8782929e+08 | H38: =H37+H30 -> 3.2132274e+08 | I38: =I37+I30 -> 3.3478556e+08 | J38: =J37+J30 -> 3.5556475e+08 | K38: =K37+K30 -> 3.7735739e+08
B40: EQUITY AND LIABILITIES
B41: Equity
B42: Share Capital | E42: 1250000 | F42: 1250000 | G42: =F42 -> 1250000 | H42: =G42 -> 1250000 | I42: =H42 -> 1250000 | J42: =I42 -> 1250000 | K42: =J42 -> 1250000
B43: Retained Earnings | E43: 51344328 | F43: 57344831 | G43: =F43+(25%*G21) -> 64768177 | H43: =G43+(25%*H21) -> 72868594 | I43: =H43+(25%*I21) -> 82000677 | J43: =I43+(25%*J21) -> 92443121 | K43: =J43+(25%*K21) -> 1.0422846e+08
B44: Actuarial Reserves | E44: -29408 | F44: 33169 | G44: =F44 -> 33169 | H44: =G44 -> 33169 | I44: =H44 -> 33169 | J44: =I44 -> 33169 | K44: =J44 -> 33169
B45: Total Equity | E45: =SUM(E42:E44) -> 52564920 | F45: =SUM(F42:F44) -> 58628000 | G45: =SUM(G42:G44) -> 66051346 | H45: =SUM(H42:H44) -> 74151763 | I45: =SUM(I42:I44) -> 83283846 | J45: =SUM(J42:J44) -> 93726290 | K45: =SUM(K42:K44) -> 1.0551163e+08
B47: Non-Current Liabilities
B48: Deferred Tax Liabilities | E48: 6979747 | F48: 4018115 | G48: ='Assumption sheet'!F96 -> 3418335.5 | H48: ='Assumption sheet'!G96 -> 3113789.6 | I48: ='Assumption sheet'!H96 -> 2885901.6 | J48: ='Assumption sheet'!I96 -> 2725809.5 | K48: ='Assumption sheet'!J96 -> 2709318
...

Sheet Assumption sheet
B2: Geregu PLC
B3: Financial Forecast 2026- 2030
B4: Assumption & calculations | D4: 2024 | E4: 2025 | F4: 2026 | G4: =F4+1 -> 2027 | H4: =G4+1 -> 2028 | I4: =H4+1 -> 2029 | J4: =I4+1 -> 2030
B6: ASSUMPTIONS & DRIVERS
B7: Macroeconomic Drivers
B8: USD / NGN Exchange Rate | C8: NGN/USD | F8: ='Scenario sheet'!E24 -> 1350 | G8: ='Scenario sheet'!F24 -> 1450 | H8: ='Scenario sheet'!G24 -> 1550 | I8: ='Scenario sheet'!H24 -> 1650 | J8: ='Scenario sheet'!I24 -> 1750
B9: Fully Loaded Gas Price (incl. Shrinkage & Levies) | C9: USD/Mscf | F9: ='Scenario sheet'!E18 -> 3.4 | G9: ='Scenario sheet'!F18 -> 3.45 | H9: ='Scenario sheet'!G18 -> 3.49 | I9: ='Scenario sheet'!H18 -> 3.53 | J9: ='Scenario sheet'!I18 -> 3.57
B11: Plant Operational Drivers
B12: Installed Capacity | C12: MW | F12: 435 | G12: 435 | H12: 435 | I12: 435 | J12: 435
B13: Plant Availability Factor | C13: % | F13: 0.88 | G13: 0.9 | H13: 0.9 | I13: 0.9 | J13: 0.9
B14: Plant Load Factor (PLF) / Dispatch Rate | C14: % | F14: 0.72 | G14: 0.75 | H14: =G14+0.01 -> 0.76 | I14: =H14+0.01 -> 0.77 | J14: =I14+0.01 -> 0.78
B15: Operating Hours | C15: Hours | F15: 8760 | G15: 8760 | H15: 8760 | I15: 8760 | J15: 8760
B16: Auxiliary Consumption Rate | C16: % | F16: 0.03 | G16: 0.03 | H16: 0.03 | I16: 0.03 | J16: 0.03
B17: Transmission Loss Factor (TLF) | C17: % | F17: 0.07 | G17: 0.07 | H17: 0.07 | I17: 0.07 | J17: 0.07
B18: Plant Heat Rate Efficiency | C18: Mscf/MWh | F18: 10.4 | G18: 10.3 | H18: 10.25 | I18: 10.2 | J18: 10.15
B20: Regulated Pricing Tariffs
B21: Wholesale Energy Tariff | C21: NGN/kWh | F21: 53 | G21: 56.5 | H21: 60 | I21: 63.5 | J21: 67
B22: Capacity Charge Rate | C22: USD/MW/Hour | F22: 20.5 | G22: 21 | H22: 21.5 | I22: 22 | J22: 22.5
B25: PP&E Assumptions & Drivers
B26: Routine Maintenance Capex | C26: % of Rev | F26: 0.01 | G26: =F26+0.5% -> 0.015 | H26: =G26+0.09% -> 0.0159 | I26: =H26+0.09% -> 0.0168 | J26: =I26+0.09% -> 0.0177
B27: Major Overhaul / Turnaround Spend | F27: 1413800 | G27: 0 | H27: 0 | I27: 0 | J27: 1500000
B28: Implied Depreciation Rate | C28: % | F28: 0.15 | G28: 0.15 | H28: 0.15 | I28: 0.15 | J28: 0.15
B30: Dividend pay out ratio | C30: % | F30: 0.75 | G30: 0.75 | H30: 0.75 | I30: 0.75 | J30: 0.75
B32: Capital allowance rate | C32: % of dep | F32: 1.05 | G32: 1.05 | H32: 1.05 | I32: 1.05 | J32: 1.05
B33: Blended Income Tax Rate | C33: % | F33: 0.34 | G33: 0.34 | H33: 0.34 | I33: 0.34 | J33: 0.34
B34: Deferred Tax Provision Rate | C34: % of PP&E | F34: 0.06 | G34: 0.06 | H34: 0.06 | I34: 0.06 | J34: 0.06
B35: Bank Borrowings Drivers
B36: Commercial Bank Borrowing Rate | C36: % | F36: 0.25 | G36: 0.22 | H36: 0.21 | I36: 0.2 | J36: 0.18
B37: LT Borrowings Principal Repayment | C37: N'000 | F37: 802707.6 | G37: 802707.6 | H37: 802707.6 | I37: 802707.6 | J37: 802707.6
B38: Corporate Bond Drivers
B39: Bond Coupon Rate (Fixed) | C39: % | F39: 0.147 | G39: 0.147 | H39: 0.147 | I39: 0.147 | J39: 0
B41: Bond Payable (Current Liability) | F41: 3322039.7 | G41: 3322039.7 | H41: 3322039.7 | I41: 0 | J41: 0
B42: Bond Payable (Non-Current Liability) | F42: 4836191.8 | G42: 4836191.8 | H42: 4836191.8 | I42: 4836191.8 | J42: 4836191.8
B47: Calculation
B49: Revenue calculation
B50: Gross power generation | F50: =F12*F15*F14 -> 2743632 | G50: =G12*G15*G14 -> 2857950 | H50: =H12*H15*H14 -> 2896056 | I50: =I12*I15*I14 -> 2934162 | J50: =J12*J15*J14 -> 2972268
B51: Net enegry sent out | F51: =F50*(1-F16) -> 2661323 | G51: =G50*(1-G16) -> 2772211.5 | H51: =H50*(1-H16) -> 2809174.3 | I51: =I50*(1-I16) -> 2846137.1 | J51: =J50*(1-J16) -> 2883100
B52: Net billable energy | F52: =F51*(1-F17) -> 2475030.4 | G52: =G51*(1-G17) -> 2578156.7 | H52: =H51*(1-H17) -> 2612532.1 | I52: =I51*(1-I17) -> 2646907.5 | J52: =J51*(1-J17) -> 2681283
B53: Energy sold revenue | F53: =F52*F21 -> 1.3117661e+08 | G53: =G52*G21 -> 1.4566585e+08 | H53: =H52*H21 -> 1.5675193e+08 | I53: =I52*I21 -> 1.6807863e+08 | J53: =J52*J21 -> 1.7964596e+08
B54: Capacity charge revenue | F54: =(F12*F15*F13*F22*F8)/1000 -> 92803352 | G54: =(G12*G15*G13*G22*G8)/1000 -> 104429493 | H54: =(H12*H15*H13*H22*H8)/1000 -> 1.1428942e+08 | I54: =(I12*I15*I13*I22*I8)/1000 -> 124492302 | J54: =(J12*J15*J13*J22*J8)/1000 -> 1.3503814e+08
...

Sheet DCF
C2: Geregu PLC | F2: Key Outputs
C3: Discounted Cash Flow Valuation | F3: WACC | G3: =D38 -> 0.1549
F4: Terminal Growth Rate (g) | G4: =D41 -> 0.0947
F5: Enterprise Value | G5: =D73 -> 5.3125892e+08
C6: 1. COST OF CAPITAL | F6: Equity Value | G6: =D76 -> 4.9501857e+08
F7: Current market Price par share | G7: 917.4
C8: Nigeria Country Risk
C9: Nigeria Default Spread (adj. for equity market volatility) | D9: 0.0552
C10: Nigeria Country Risk Premium (CRP) | D10: 0.0841
C11: Nigeria Total Equity Risk Premium (= Mature Market ERP + Nigeria CRP) | D11: 0.1264
C12: Risk-Free Rate, NGN (= Rf US$ + Nigeria Default Spread) | D12: 0.0947
C14: Beta
C15: Power Industry Unlevered Beta (Global comparables) | D15: 0.43
C16: Geregu Total Interest-Bearing Debt (FY2025A, book value, N'000) | D16: 68087065
C17: Geregu Total Equity (FY2025A, book value, N'000) | D17: 58628000
C18: Debt / Equity (book value, FY2025A) | D18: =D17/D16 -> 0.86107398
C19: Marginal Tax Rate (linked to 3-statement model) | D19: ='Assumption sheet'!F33 -> 0.34
C20: Relevered Beta (= Unlevered β × [1 + (1−t) × D/E]) | D20: 0.76
C22: Cost of Equity
C23: Cost of Equity (Ke) = Rf,NGN + Relevered β × Nigeria Total ERP | D23: 0.1907
C26: 2025 Finance Cost (interest expense) | D26: 12589544
C27: 2024Total Interest-Bearing Debt | D27: 65820275
C28: 2025 Total Interest-Bearing Debt | D28: 68087065
C29: Average Total Debt (FY2024A–FY2025A) | D29: 66953670
C30: Pre-Tax Cost of Debt (Kd) = Finance Cost / Average Total Debt | D30: 0.188
C31: After-Tax Cost of Debt = Kd × (1 − t) | D31: 0.1241
C33: Capital Structure Weights (book value, FY2025A)
C34: Weight of Debt, D / (D+E) | D34: 0.5373
C35: Weight of Equity, E / (D+E) | D35: 0.4627
C37: WACC
C38: WACC = (E/V × Ke) + (D/V × Kd × (1−t)) | D38: 0.1549
C40: Terminal Growth Rate
C41: Terminal Growth Rate (g) — capped at Risk-Free Rate, NGN | D41: 0.0947
C44: 2. UNLEVERED FREE CASH FLOW (FCFF)
C46: Fiscal Year | E46: 2026 | F46: 2027 | G46: 2028 | H46: 2029 | I46: 2030
C47: EBIT (Operating Profit) | E47: =Model!G16 -> 56611769 | F47: =Model!H16 -> 64749793 | G47: =Model!I16 -> 70658470 | H47: =Model!J16 -> 76738256 | I47: =Model!K16 -> 82589459
C48: Tax Rate (linked to Assumption sheet) | E48: ='Assumption sheet'!F33 -> 0.34 | F48: ='Assumption sheet'!G33 -> 0.34 | G48: ='Assumption sheet'!H33 -> 0.34 | H48: ='Assumption sheet'!I33 -> 0.34 | I48: ='Assumption sheet'!J33 -> 0.34
C49: NOPAT = EBIT × (1 − Tax Rate) | E49: =E47*(1-E48) -> 37363768 | F49: =F47*(1-F48) -> 42734863 | G49: =G47*(1-G48) -> 46634590 | H49: =H47*(1-H48) -> 50647249 | I49: =I47*(1-I48) -> 54509043
C50: Depreciation & Amortization | E50: =-Model!G15 -> 9731551.6 | F50: =-Model!H15 -> 8827196.1 | G50: =-Model!I15 -> 8107690.8 | H50: =-Model!J15 -> 7583393.3 | I50: =-Model!K15 -> 7344766.8
C51: Capital Expenditure | E51: =-'Assumption sheet'!F65 -> -3653599.7 | F51: =-'Assumption sheet'!G65 -> -3751430.2 | G51: =-'Assumption sheet'!H65 -> -4309557.4 | H51: =-'Assumption sheet'!I65 -> -4915191.6 | I51: =-'Assumption sheet'!J65 -> -7069908.5
...

Sheet Scenario sheet
B2: Geregu PLC
B3: Financial Forecast 2026- 2030
B4: Scenario sheet | E4: 2026 | F4: =E4+1 -> 2027 | G4: =F4+1 -> 2028 | H4: =G4+1 -> 2029 | I4: =H4+1 -> 2030
B7: Base Case | D7: 1
B8: Bull Case
B9: Bear Case
B11: Inflation
B12: Used in model | E12: {=INDEX(E13:E15,S_scenario)} -> 0.18 | F12: {=INDEX(F13:F15,S_scenario)} -> 0.15 | G12: {=INDEX(G13:G15,S_scenario)} -> 0.12 | H12: {=INDEX(H13:H15,S_scenario)} -> 0.1 | I12: {=INDEX(I13:I15,S_scenario)} -> 0.095
B13: Base Case | E13: 0.18 | F13: 0.15 | G13: 0.12 | H13: 0.1 | I13: 0.095
B14: Bull Case | E14: 0.14 | F14: 0.11 | G14: 0.09 | H14: 0.075 | I14: 0.06
B15: Bear Case | E15: 0.25 | F15: 0.22 | G15: 0.18 | H15: 0.16 | I15: 0.15
B17: Fully Loaded Gas Price Matrix
B18: Used in model | E18: {=INDEX(E19:E21,S_scenario)} -> 3.4 | F18: {=INDEX(F19:F21,S_scenario)} -> 3.45 | G18: {=INDEX(G19:G21,S_scenario)} -> 3.49 | H18: {=INDEX(H19:H21,S_scenario)} -> 3.53 | I18: {=INDEX(I19:I21,S_scenario)} -> 3.57
B19: Base Case | E19: 3.4 | F19: 3.45 | G19: 3.49 | H19: 3.53 | I19: 3.57
B20: Bull Case | E20: 3.35 | F20: 3.32 | G20: 3.3 | H20: 3.3 | I20: 3.3
B21: Bear Case | E21: 3.75 | F21: 3.85 | G21: 3.92 | H21: 4.05 | I21: 4.15
B23: USD / NGN Exchange Rate
B24: Used in model | E24: {=INDEX(E25:E27,S_scenario)} -> 1350 | F24: {=INDEX(F25:F27,S_scenario)} -> 1450 | G24: {=INDEX(G25:G27,S_scenario)} -> 1550 | H24: {=INDEX(H25:H27,S_scenario)} -> 1650 | I24: {=INDEX(I25:I27,S_scenario)} -> 1750
B25: Base Case | E25: 1350 | F25: 1450 | G25: 1550 | H25: 1650 | I25: 1750
B26: Bull Case | E26: 1200 | F26: 1250 | G26: 1300 | H26: 1350 | I26: 1400
B27: Bear Case | E27: 1650 | F27: 1800 | G27: 1950 | H27: 2100 | I27: 2200
